Workbook

Sheet Voltage Summary
A1: RF STAGE 1 - VOLTAGE REQUIREMENTS SUMMARY
A3: WHY RAIL 1 AND RAIL 2?
A4: Some components require TWO voltage supplies (e.g., +5V AND -5V). Rail 1 contains the primary voltage, and Rail 2 contains the secondary voltage when needed. Passive components show "None (passive)" and require no power supply.
A7: SWITCH MATRIX ENCLOSURE - VOLTAGE REQUIREMENTS
A8: Voltage Type | B8: Total Current (A) | C8: Components Using This Voltage
A9: +5 V | B9: 1.6 | C9: TTL-1SP8T-183 (x8)
A10: -5 V | B10: 0.2 | C10: TTL-1SP8T-183 (x8)
A12: ALL VOLTAGE TYPES IN COMPONENT CATALOG
A13: Voltage Type | B13: Voltage Range | C13: Max Current/Unit (A) | D13: Example Components
A14: +3 V | B14: 2.7V to 3.6V | C14: 0.003 | D14: ZX76-31A-PNS+
A15: +3.3 V | B15: 2.33V to 5.4V | C15: 0.00025 | D15: ZX76-24G-30-S+
A16: +5 V | B16: 4.5V to 5.5V | C16: 0.28 | D16: ZVA-443X+, TTL-1SP8T-183, 50P-2101 (+3 more)
A17: +12 V | B17: 11.0V to 13.8V | C17: 0.43 | D17: MSP2TA-18-12+ (energized), MSP2TA-18-12+ (de-energized), OD3010-12HB fan (+2 more)
A18: +15 V | B18: See datasheet | C18: 0.105 | D18: ZFL-1000+
A19: +28 V | B19: See datasheet | C19: 0.432 | D19: PA-124-D (all cells energized)
A20: -3 V | B20: -3.3V to -2.7V | C20: 4e-05 | D20: ZX76-24G-30-S+
A21: -3.3 V | B21: -3.6V to -3.2V | C21: 4e-05 | D21: ZX76-31A-PNS+
A22: -5 V | B22: -5.25V to -4.75V | C22: 0.025 | D22: TTL-1SP8T-183
A24: COMPONENTS REQUIRING DUAL VOLTAGE SUPPLIES
A25: Component | B25: Rail 1 Voltage | C25: Rail 1 Current (A) | D25: Rail 2 Voltage | E25: Rail 2 Current (A)
A26: ZX76-31A-PNS+ | B26: +3 V | C26: 0.003 | D26: -3.3 V | E26: 4e-05
A27: TTL-1SP8T-183 | B27: +5 V | C27: 0.2 | D27: -5 V | E27: 0.025
A28: ZX76-24G-30-S+ | B28: +3.3 V | C28: 0.00025 | D28: -3 V | E28: 4e-05

Sheet Switch Matrix
A2: Enclosure 1 heat analysis | J2: Sum of max amps per voltage type (from rows 11-70)
A3: Enclosure name | B3: Switch Matrix | D3: CFM | J3: Voltage type | K3: +3 V | L3: +3.3 V | M3: +5 V | N3: +12 V | O3: +15 V | P3: +28 V | Q3: -3 V | R3: -3.3 V | S3: -5 V
A4: Known heat subtotal (W) | B4: =SUM(F11:F70) | J4: Sum max A | K4: =SUMIF($J$11:$J$70,K$3,$O$11:$O$70)+SUMIF($P$11:$P$70,K$3,$U$11:$U$70) | L4: =SUMIF($J$11:$J$70,L$3,$O$11:$O$70)+SUMIF($P$11:$P$70,L$3,$U$11:$U$70) | M4: =SUMIF($J$11:$J$70,M$3,$O$11:$O$70)+SUMIF($P$11:$P$70,M$3,$U$11:$U$70) | N4: =SUMIF($J$11:$J$70,N$3,$O$11:$O$70)+SUMIF($P$11:$P$70,N$3,$U$11:$U$70) | O4: =SUMIF($J$11:$J$70,O$3,$O$11:$O$70)+SUMIF($P$11:$P$70,O$3,$U$11:$U$70) | P4: =SUMIF($J$11:$J$70,P$3,$O$11:$O$70)+SUMIF($P$11:$P$70,P$3,$U$11:$U$70) | Q4: =SUMIF($J$11:$J$70,Q$3,$O$11:$O$70)+SUMIF($P$11:$P$70,Q$3,$U$11:$U$70) | R4: =SUMIF($J$11:$J$70,R$3,$O$11:$O$70)+SUMIF($P$11:$P$70,R$3,$U$11:$U$70) | S4: =SUMIF($J$11:$J$70,S$3,$O$11:$O$70)+SUMIF($P$11:$P$70,S$3,$U$11:$U$70)
A5: Total status | B5: =IF(COUNTA(A11:A70)=0,"No components",IF(COUNTIF(G11:G70,"Needs*")+COUNTIF(G11:G70,"Invalid*")>0,"Incomplete","Calculated; review basis")) | J5: Check (=0) | K5: =SUM($O$11:$O$70)+SUM($U$11:$U$70)-SUM($K$4:$S$4)
J6: Check = amps on voltage types not listed in row 3. If it is not 0, add that voltage type to row 3.
A7: 1. Select a component in column A. 2. Enter quantity in B. 3. Review the heat basis in I.
A8: Optional: enter actual W/unit in D. Blank uses the catalog; zero is a valid override. Amber = editable.
A9: 60 rows per enclosure. Duplicate this tab for another enclosure; add a link on Summary if needed.
A10: Component / operating case | B10: Quantity | C10: Catalog W/unit | D10: Override W/unit | E10: Applied W/unit | F10: Total heat W | G10: Row status | I10: Basis / notes | J10: Rail 1 voltage type | K10: Rail 1 V min | L10: Rail 1 V recommended | M10: Rail 1 V max | N10: Rail 1 max A/unit | O10: Rail 1 max A total | P10: Rail 2 voltage type | Q10: Rail 2 V min | R10: Rail 2 V recommended | S10: Rail 2 V max | T10: Rail 2 max A/unit | U10: Rail 2 max A total
A11: TTL-1SP8T-183 | B11: 8 | C11: =IF(A11="","",IF(COUNTIF(Components!$A$8:$A$107,A11)<>1,"Pending",VLOOKUP(A11,Components!$A$8:$F$107,5,FALSE))) | E11: =IF(A11="","",IF(ISBLANK(D11),C11,IF(AND(ISNUMBER(D11),D11>=0),D11,"Pending"))) | F11: =IF(OR(G11="Catalog basis",G11="Override used"),B11*E11,"") | G11: =IF(A11="",IF(OR(NOT(ISBLANK(B11)),NOT(ISBLANK(D11))),"Needs component",""),IF(COUNTIF(Components!$A$8:$A$107,A11)<>1,"Invalid component",IF(ISBLANK(B11),"Needs quantity",IF(NOT(ISNUMBER(B11)),"Invalid quantity",IF(OR(B11<0,B11<>INT(B11)),"Invalid quantity",IF(NOT(ISNUMBER(E11)),"Needs heat input",IF(NOT(ISBLANK(D11)),"Override used","Catalog basis"))))))) | I11: =IF(A11="","",IF(COUNTIF(Components!$A$8:$A$107,A11)<>1,"Select a unique catalog component",VLOOKUP(A11,Components!$A$8:$F$107,6,FALSE))) | J11: =IF(OR(A11="",COUNTIF(Components!$A$8:$A$107,A11)<>1),"",IF(VLOOKUP(A11,Components!$A$8:$S$107,9,FALSE)="","",VLOOKUP(A11,Components!$A$8:$S$107,9,FALSE))) | K11: =IF(OR(A11="",COUNTIF(Components!$A$8:$A$107,A11)<>1),"",IF(VLOOKUP(A11,Components!$A$8:$S$107,10,FALSE)="","",VLOOKUP(A11,Components!$A$8:$S$107,10,FALSE))) | L11: =IF(OR(A11="",COUNTIF(Components!$A$8:$A$107,A11)<>1),"",IF(VLOOKUP(A11,Components!$A$8:$S$107,11,FALSE)="","",VLOOKUP(A11,Components!$A$8:$S$107,11,FALSE))) | M11: =IF(OR(A11="",COUNTIF(Components!$A$8:$A$107,A11)<>1),"",IF(VLOOKUP(A11,Components!$A$8:$S$107,12,FALSE)="","",VLOOKUP(A11,Components!$A$8:$S$107,12,FALSE))) | N11: =IF(OR(A11="",COUNTIF(Components!$A$8:$A$107,A11)<>1),"",IF(VLOOKUP(A11,Components!$A$8:$S$107,13,FALSE)="","",VLOOKUP(A11,Components!$A$8:$S$107,13,FALSE))) | O11: =IF(OR(N11="",NOT(ISNUMBER(B11))),"",B11*N11) | P11: =IF(OR(A11="",COUNTIF(Components!$A$8:$A$107,A11)<>1),"",IF(VLOOKUP(A11,Components!$A$8:$S$107,14,FALSE)="","",VLOOKUP(A11,Components!$A$8:$S$107,14,FALSE))) | Q11: =IF(OR(A11="",COUNTIF(Components!$A$8:$A$107,A11)<>1),"",IF(VLOOKUP(A11,Components!$A$8:$S$107,15,FALSE)="","",VLOOKUP(A11,Components!$A$8:$S$107,15,FALSE))) | R11: =IF(OR(A11="",COUNTIF(Components!$A$8:$A$107,A11)<>1),"",IF(VLOOKUP(A11,Components!$A$8:$S$107,16,FALSE)="","",VLOOKUP(A11,Components!$A$8:$S$107,16,FALSE))) | S11: =IF(OR(A11="",COUNTIF(Components!$A$8:$A$107,A11)<>1),"",IF(VLOOKUP(A11,Components!$A$8:$S$107,17,FALSE)="","",VLOOKUP(A11,Components!$A$8:$S$107,17,FALSE))) | T11: =IF(OR(A11="",COUNTIF(Components!$A$8:$A$107,A11)<>1),"",IF(VLOOKUP(A11,Components!$A$8:$S$107,18,FALSE)="","",VLOOKUP(A11,Components!$A$8:$S$107,18,FALSE))) | U11: =IF(OR(T11="",NOT(ISNUMBER(B11))),"",B11*T11)
A12: BW-S0.5W2+ | B12: 8 | C12: =IF(A12="","",IF(COUNTIF(Components!$A$8:$A$107,A12)<>1,"Pending",VLOOKUP(A12,Components!$A$8:$F$107,5,FALSE))) | E12: =IF(A12="","",IF(ISBLANK(D12),C12,IF(AND(ISNUMBER(D12),D12>=0),D12,"Pending"))) | F12: =IF(OR(G12="Catalog basis",G12="Override used"),B12*E12,"") | G12: =IF(A12="",IF(OR(NOT(ISBLANK(B12)),NOT(ISBLANK(D12))),"Needs component",""),IF(COUNTIF(Components!$A$8:$A$107,A12)<>1,"Invalid component",IF(ISBLANK(B12),"Needs quantity",IF(NOT(ISNUMBER(B12)),"Invalid quantity",IF(OR(B12<0,B12<>INT(B12)),"Invalid quantity",IF(NOT(ISNUMBER(E12)),"Needs heat input",IF(NOT(ISBLANK(D12)),"Override used","Catalog basis"))))))) | I12: =IF(A12="","",IF(COUNTIF(Components!$A$8:$A$107,A12)<>1,"Select a unique catalog component",VLOOKUP(A12,Components!$A$8:$F$107,6,FALSE))) | J12: =IF(OR(A12="",COUNTIF(Components!$A$8:$A$107,A12)<>1),"",IF(VLOOKUP(A12,Components!$A$8:$S$107,9,FALSE)="","",VLOOKUP(A12,Components!$A$8:$S$107,9,FALSE))) | K12: =IF(OR(A12="",COUNTIF(Components!$A$8:$A$107,A12)<>1),"",IF(VLOOKUP(A12,Components!$A$8:$S$107,10,FALSE)="","",VLOOKUP(A12,Components!$A$8:$S$107,10,FALSE))) | L12: =IF(OR(A12="",COUNTIF(Components!$A$8:$A$107,A12)<>1),"",IF(VLOOKUP(A12,Components!$A$8:$S$107,11,FALSE)="","",VLOOKUP(A12,Components!$A$8:$S$107,11,FALSE))) | M12: =IF(OR(A12="",COUNTIF(Components!$A$8:$A$107,A12)<>1),"",IF(VLOOKUP(A12,Components!$A$8:$S$107,12,FALSE)="","",VLOOKUP(A12,Components!$A$8:$S$107,12,FALSE))) | N12: =IF(OR(A12="",COUNTIF(Components!$A$8:$A$107,A12)<>1),"",IF(VLOOKUP(A12,Components!$A$8:$S$107,13,FALSE)="","",VLOOKUP(A12,Components!$A$8:$S$107,13,FALSE))) | O12: =IF(OR(N12="",NOT(ISNUMBER(B12))),"",B12*N12) | P12: =IF(OR(A12="",COUNTIF(Components!$A$8:$A$107,A12)<>1),"",IF(VLOOKUP(A12,Components!$A$8:$S$107,14,FALSE)="","",VLOOKUP(A12,Components!$A$8:$S$107,14,FALSE))) | Q12: =IF(OR(A12="",COUNTIF(Components!$A$8:$A$107,A12)<>1),"",IF(VLOOKUP(A12,Components!$A$8:$S$107,15,FALSE)="","",VLOOKUP(A12,Components!$A$8:$S$107,15,FALSE))) | R12: =IF(OR(A12="",COUNTIF(Components!$A$8:$A$107,A12)<>1),"",IF(VLOOKUP(A12,Components!$A$8:$S$107,16,FALSE)="","",VLOOKUP(A12,Components!$A$8:$S$107,16,FALSE))) | S12: =IF(OR(A12="",COUNTIF(Components!$A$8:$A$107,A12)<>1),"",IF(VLOOKUP(A12,Components!$A$8:$S$107,17,FALSE)="","",VLOOKUP(A12,Components!$A$8:$S$107,17,FALSE))) | T12: =IF(OR(A12="",COUNTIF(Components!$A$8:$A$107,A12)<>1),"",IF(VLOOKUP(A12,Components!$A$8:$S$107,18,FALSE)="","",VLOOKUP(A12,Components!$A$8:$S$107,18,FALSE))) | U12: =IF(OR(T12="",NOT(ISNUMBER(B12))),"",B12*T12)
A13: RFLT8WDC40G | B13: 8 | C13: =IF(A13="","",IF(COUNTIF(Components!$A$8:$A$107,A13)<>1,"Pending",VLOOKUP(A13,Components!$A$8:$F$107,5,FALSE))) | E13: =IF(A13="","",IF(ISBLANK(D13),C13,IF(AND(ISNUMBER(D13),D13>=0),D13,"Pending"))) | F13: =IF(OR(G13="Catalog basis",G13="Override used"),B13*E13,"") | G13: =IF(A13="",IF(OR(NOT(ISBLANK(B13)),NOT(ISBLANK(D13))),"Needs component",""),IF(COUNTIF(Components!$A$8:$A$107,A13)<>1,"Invalid component",IF(ISBLANK(B13),"Needs quantity",IF(NOT(ISNUMBER(B13)),"Invalid quantity",IF(OR(B13<0,B13<>INT(B13)),"Invalid quantity",IF(NOT(ISNUMBER(E13)),"Needs heat input",IF(NOT(ISBLANK(D13)),"Override used","Catalog basis"))))))) | I13: =IF(A13="","",IF(COUNTIF(Components!$A$8:$A$107,A13)<>1,"Select a unique catalog component",VLOOKUP(A13,Components!$A$8:$F$107,6,FALSE))) | J13: =IF(OR(A13="",COUNTIF(Components!$A$8:$A$107,A13)<>1),"",IF(VLOOKUP(A13,Components!$A$8:$S$107,9,FALSE)="","",VLOOKUP(A13,Components!$A$8:$S$107,9,FALSE))) | K13: =IF(OR(A13="",COUNTIF(Components!$A$8:$A$107,A13)<>1),"",IF(VLOOKUP(A13,Components!$A$8:$S$107,10,FALSE)="","",VLOOKUP(A13,Components!$A$8:$S$107,10,FALSE))) | L13: =IF(OR(A13="",COUNTIF(Components!$A$8:$A$107,A13)<>1),"",IF(VLOOKUP(A13,Components!$A$8:$S$107,11,FALSE)="","",VLOOKUP(A13,Components!$A$8:$S$107,11,FALSE))) | M13: =IF(OR(A13="",COUNTIF(Components!$A$8:$A$107,A13)<>1),"",IF(VLOOKUP(A13,Components!$A$8:$S$107,12,FALSE)="","",VLOOKUP(A13,Components!$A$8:$S$107,12,FALSE))) | N13: =IF(OR(A13="",COUNTIF(Components!$A$8:$A$107,A13)<>1),"",IF(VLOOKUP(A13,Components!$A$8:$S$107,13,FALSE)="","",VLOOKUP(A13,Components!$A$8:$S$107,13,FALSE))) | O13: =IF(OR(N13="",NOT(ISNUMBER(B13))),"",B13*N13) | P13: =IF(OR(A13="",COUNTIF(Components!$A$8:$A$107,A13)<>1),"",IF(VLOOKUP(A13,Components!$A$8:$S$107,14,FALSE)="","",VLOOKUP(A13,Components!$A$8:$S$107,14,FALSE))) | Q13: =IF(OR(A13="",COUNTIF(Components!$A$8:$A$107,A13)<>1),"",IF(VLOOKUP(A13,Components!$A$8:$S$107,15,FALSE)="","",VLOOKUP(A13,Components!$A$8:$S$107,15,FALSE))) | R13: =IF(OR(A13="",COUNTIF(Components!$A$8:$A$107,A13)<>1),"",IF(VLOOKUP(A13,Components!$A$8:$S$107,16,FALSE)="","",VLOOKUP(A13,Components!$A$8:$S$107,16,FALSE))) | S13: =IF(OR(A13="",COUNTIF(Components!$A$8:$A$107,A13)<>1),"",IF(VLOOKUP(A13,Components!$A$8:$S$107,17,FALSE)="","",VLOOKUP(A13,Components!$A$8:$S$107,17,FALSE))) | T13: =IF(OR(A13="",COUNTIF(Components!$A$8:$A$107,A13)<>1),"",IF(VLOOKUP(A13,Components!$A$8:$S$107,18,FALSE)="","",VLOOKUP(A13,Components!$A$8:$S$107,18,FALSE))) | U13: =IF(OR(T13="",NOT(ISNUMBER(B13))),"",B13*T13)
C14: =IF(A14="","",IF(COUNTIF(Components!$A$8:$A$107,A14)<>1,"Pending",VLOOKUP(A14,Components!$A$8:$F$107,5,FALSE))) | E14: =IF(A14="","",IF(ISBLANK(D14),C14,IF(AND(ISNUMBER(D14),D14>=0),D14,"Pending"))) | F14: =IF(OR(G14="Catalog basis",G14="Override used"),B14*E14,"") | G14: =IF(A14="",IF(OR(NOT(ISBLANK(B14)),NOT(ISBLANK(D14))),"Needs component",""),IF(COUNTIF(Components!$A$8:$A$107,A14)<>1,"Invalid component",IF(ISBLANK(B14),"Needs quantity",IF(NOT(ISNUMBER(B14)),"Invalid quantity",IF(OR(B14<0,B14<>INT(B14)),"Invalid quantity",IF(NOT(ISNUMBER(E14)),"Needs heat input",IF(NOT(ISBLANK(D14)),"Override used","Catalog basis"))))))) | I14: =IF(A14="","",IF(COUNTIF(Components!$A$8:$A$107,A14)<>1,"Select a unique catalog component",VLOOKUP(A14,Components!$A$8:$F$107,6,FALSE))) | J14: =IF(OR(A14="",COUNTIF(Components!$A$8:$A$107,A14)<>1),"",IF(VLOOKUP(A14,Components!$A$8:$S$107,9,FALSE)="","",VLOOKUP(A14,Components!$A$8:$S$107,9,FALSE))) | K14: =IF(OR(A14="",COUNTIF(Components!$A$8:$A$107,A14)<>1),"",IF(VLOOKUP(A14,Components!$A$8:$S$107,10,FALSE)="","",VLOOKUP(A14,Components!$A$8:$S$107,10,FALSE))) | L14: =IF(OR(A14="",COUNTIF(Components!$A$8:$A$107,A14)<>1),"",IF(VLOOKUP(A14,Components!$A$8:$S$107,11,FALSE)="","",VLOOKUP(A14,Components!$A$8:$S$107,11,FALSE))) | M14: =IF(OR(A14="",COUNTIF(Components!$A$8:$A$107,A14)<>1),"",IF(VLOOKUP(A14,Components!$A$8:$S$107,12,FALSE)="","",VLOOKUP(A14,Components!$A$8:$S$107,12,FALSE))) | N14: =IF(OR(A14="",COUNTIF(Components!$A$8:$A$107,A14)<>1),"",IF(VLOOKUP(A14,Components!$A$8:$S$107,13,FALSE)="","",VLOOKUP(A14,Components!$A$8:$S$107,13,FALSE))) | O14: =IF(OR(N14="",NOT(ISNUMBER(B14))),"",B14*N14) | P14: =IF(OR(A14="",COUNTIF(Components!$A$8:$A$107,A14)<>1),"",IF(VLOOKUP(A14,Components!$A$8:$S$107,14,FALSE)="","",VLOOKUP(A14,Components!$A$8:$S$107,14,FALSE))) | Q14: =IF(OR(A14="",COUNTIF(Components!$A$8:$A$107,A14)<>1),"",IF(VLOOKUP(A14,Components!$A$8:$S$107,15,FALSE)="","",VLOOKUP(A14,Components!$A$8:$S$107,15,FALSE))) | R14: =IF(OR(A14="",COUNTIF(Components!$A$8:$A$107,A14)<>1),"",IF(VLOOKUP(A14,Components!$A$8:$S$107,16,FALSE)="","",VLOOKUP(A14,Components!$A$8:$S$107,16,FALSE))) | S14: =IF(OR(A14="",COUNTIF(Components!$A$8:$A$107,A14)<>1),"",IF(VLOOKUP(A14,Components!$A$8:$S$107,17,FALSE)="","",VLOOKUP(A14,Components!$A$8:$S$107,17,FALSE))) | T14: =IF(OR(A14="",COUNTIF(Components!$A$8:$A$107,A14)<>1),"",IF(VLOOKUP(A14,Components!$A$8:$S$107,18,FALSE)="","",VLOOKUP(A14,Components!$A$8:$S$107,18,FALSE))) | U14: =IF(OR(T14="",NOT(ISNUMBER(B14))),"",B14*T14)
C15: =IF(A15="","",IF(COUNTIF(Components!$A$8:$A$107,A15)<>1,"Pending",VLOOKUP(A15,Components!$A$8:$F$107,5,FALSE))) | E15: =IF(A15="","",IF(ISBLANK(D15),C15,IF(AND(ISNUMBER(D15),D15>=0),D15,"Pending"))) | F15: =IF(OR(G15="Catalog basis",G15="Override used"),B15*E15,"") | G15: =IF(A15="",IF(OR(NOT(ISBLANK(B15)),NOT(ISBLANK(D15))),"Needs component",""),IF(COUNTIF(Components!$A$8:$A$107,A15)<>1,"Invalid component",IF(ISBLANK(B15),"Needs quantity",IF(NOT(ISNUMBER(B15)),"Invalid quantity",IF(OR(B15<0,B15<>INT(B15)),"Invalid quantity",IF(NOT(ISNUMBER(E15)),"Needs heat input",IF(NOT(ISBLANK(D15)),"Override used","Catalog basis"))))))) | I15: =IF(A15="","",IF(COUNTIF(Components!$A$8:$A$107,A15)<>1,"Select a unique catalog component",VLOOKUP(A15,Components!$A$8:$F$107,6,FALSE))) | J15: =IF(OR(A15="",COUNTIF(Components!$A$8:$A$107,A15)<>1),"",IF(VLOOKUP(A15,Components!$A$8:$S$107,9,FALSE)="","",VLOOKUP(A15,Components!$A$8:$S$107,9,FALSE))) | K15: =IF(OR(A15="",COUNTIF(Components!$A$8:$A$107,A15)<>1),"",IF(VLOOKUP(A15,Components!$A$8:$S$107,10,FALSE)="","",VLOOKUP(A15,Components!$A$8:$S$107,10,FALSE))) | L15: =IF(OR(A15="",COUNTIF(Components!$A$8:$A$107,A15)<>1),"",IF(VLOOKUP(A15,Components!$A$8:$S$107,11,FALSE)="","",VLOOKUP(A15,Components!$A$8:$S$107,11,FALSE))) | M15: =IF(OR(A15="",COUNTIF(Components!$A$8:$A$107,A15)<>1),"",IF(VLOOKUP(A15,Components!$A$8:$S$107,12,FALSE)="","",VLOOKUP(A15,Components!$A$8:$S$107,12,FALSE))) | N15: =IF(OR(A15="",COUNTIF(Components!$A$8:$A$107,A15)<>1),"",IF(VLOOKUP(A15,Components!$A$8:$S$107,13,FALSE)="","",VLOOKUP(A15,Components!$A$8:$S$107,13,FALSE))) | O15: =IF(OR(N15="",NOT(ISNUMBER(B15))),"",B15*N15) | P15: =IF(OR(A15="",COUNTIF(Components!$A$8:$A$107,A15)<>1),"",IF(VLOOKUP(A15,Components!$A$8:$S$107,14,FALSE)="","",VLOOKUP(A15,Components!$A$8:$S$107,14,FALSE))) | Q15: =IF(OR(A15="",COUNTIF(Components!$A$8:$A$107,A15)<>1),"",IF(VLOOKUP(A15,Components!$A$8:$S$107,15,FALSE)="","",VLOOKUP(A15,Components!$A$8:$S$107,15,FALSE))) | R15: =IF(OR(A15="",COUNTIF(Components!$A$8:$A$107,A15)<>1),"",IF(VLOOKUP(A15,Components!$A$8:$S$107,16,FALSE)="","",VLOOKUP(A15,Components!$A$8:$S$107,16,FALSE))) | S15: =IF(OR(A15="",COUNTIF(Components!$A$8:$A$107,A15)<>1),"",IF(VLOOKUP(A15,Components!$A$8:$S$107,17,FALSE)="","",VLOOKUP(A15,Components!$A$8:$S$107,17,FALSE))) | T15: =IF(OR(A15="",COUNTIF(Components!$A$8:$A$107,A15)<>1),"",IF(VLOOKUP(A15,Components!$A$8:$S$107,18,FALSE)="","",VLOOKUP(A15,Components!$A$8:$S$107,18,FALSE))) | U15: =IF(OR(T15="",NOT(ISNUMBER(B15))),"",B15*T15)
C16: =IF(A16="","",IF(COUNTIF(Components!$A$8:$A$107,A16)<>1,"Pending",VLOOKUP(A16,Components!$A$8:$F$107,5,FALSE))) | E16: =IF(A16="","",IF(ISBLANK(D16),C16,IF(AND(ISNUMBER(D16),D16>=0),D16,"Pending"))) | F16: =IF(OR(G16="Catalog basis",G16="Override used"),B16*E16,"") | G16: =IF(A16="",IF(OR(NOT(ISBLANK(B16)),NOT(ISBLANK(D16))),"Needs component",""),IF(COUNTIF(Components!$A$8:$A$107,A16)<>1,"Invalid component",IF(ISBLANK(B16),"Needs quantity",IF(NOT(ISNUMBER(B16)),"Invalid quantity",IF(OR(B16<0,B16<>INT(B16)),"Invalid quantity",IF(NOT(ISNUMBER(E16)),"Needs heat input",IF(NOT(ISBLANK(D16)),"Override used","Catalog basis"))))))) | I16: =IF(A16="","",IF(COUNTIF(Components!$A$8:$A$107,A16)<>1,"Select a unique catalog component",VLOOKUP(A16,Components!$A$8:$F$107,6,FALSE))) | J16: =IF(OR(A16="",COUNTIF(Components!$A$8:$A$107,A16)<>1),"",IF(VLOOKUP(A16,Components!$A$8:$S$107,9,FALSE)="","",VLOOKUP(A16,Components!$A$8:$S$107,9,FALSE))) | K16: =IF(OR(A16="",COUNTIF(Components!$A$8:$A$107,A16)<>1),"",IF(VLOOKUP(A16,Components!$A$8:$S$107,10,FALSE)="","",VLOOKUP(A16,Components!$A$8:$S$107,10,FALSE))) | L16: =IF(OR(A16="",COUNTIF(Components!$A$8:$A$107,A16)<>1),"",IF(VLOOKUP(A16,Components!$A$8:$S$107,11,FALSE)="","",VLOOKUP(A16,Components!$A$8:$S$107,11,FALSE))) | M16: =IF(OR(A16="",COUNTIF(Components!$A$8:$A$107,A16)<>1),"",IF(VLOOKUP(A16,Components!$A$8:$S$107,12,FALSE)="","",VLOOKUP(A16,Components!$A$8:$S$107,12,FALSE))) | N16: =IF(OR(A16="",COUNTIF(Components!$A$8:$A$107,A16)<>1),"",IF(VLOOKUP(A16,Components!$A$8:$S$107,13,FALSE)="","",VLOOKUP(A16,Components!$A$8:$S$107,13,FALSE))) | O16: =IF(OR(N16="",NOT(ISNUMBER(B16))),"",B16*N16) | P16: =IF(OR(A16="",COUNTIF(Components!$A$8:$A$107,A16)<>1),"",IF(VLOOKUP(A16,Components!$A$8:$S$107,14,FALSE)="","",VLOOKUP(A16,Components!$A$8:$S$107,14,FALSE))) | Q16: =IF(OR(A16="",COUNTIF(Components!$A$8:$A$107,A16)<>1),"",IF(VLOOKUP(A16,Components!$A$8:$S$107,15,FALSE)="","",VLOOKUP(A16,Components!$A$8:$S$107,15,FALSE))) | R16: =IF(OR(A16="",COUNTIF(Components!$A$8:$A$107,A16)<>1),"",IF(VLOOKUP(A16,Components!$A$8:$S$107,16,FALSE)="","",VLOOKUP(A16,Components!$A$8:$S$107,16,FALSE))) | S16: =IF(OR(A16="",COUNTIF(Components!$A$8:$A$107,A16)<>1),"",IF(VLOOKUP(A16,Components!$A$8:$S$107,17,FALSE)="","",VLOOKUP(A16,Components!$A$8:$S$107,17,FALSE))) | T16: =IF(OR(A16="",COUNTIF(Components!$A$8:$A$107,A16)<>1),"",IF(VLOOKUP(A16,Components!$A$8:$S$107,18,FALSE)="","",VLOOKUP(A16,Components!$A$8:$S$107,18,FALSE))) | U16: =IF(OR(T16="",NOT(ISNUMBER(B16))),"",B16*T16)
C17: =IF(A17="","",IF(COUNTIF(Components!$A$8:$A$107,A17)<>1,"Pending",VLOOKUP(A17,Components!$A$8:$F$107,5,FALSE))) | E17: =IF(A17="","",IF(ISBLANK(D17),C17,IF(AND(ISNUMBER(D17),D17>=0),D17,"Pending"))) | F17: =IF(OR(G17="Catalog basis",G17="Override used"),B17*E17,"") | G17: =IF(A17="",IF(OR(NOT(ISBLANK(B17)),NOT(ISBLANK(D17))),"Needs component",""),IF(COUNTIF(Components!$A$8:$A$107,A17)<>1,"Invalid component",IF(ISBLANK(B17),"Needs quantity",IF(NOT(ISNUMBER(B17)),"Invalid quantity",IF(OR(B17<0,B17<>INT(B17)),"Invalid quantity",IF(NOT(ISNUMBER(E17)),"Needs heat input",IF(NOT(ISBLANK(D17)),"Override used","Catalog basis"))))))) | I17: =IF(A17="","",IF(COUNTIF(Components!$A$8:$A$107,A17)<>1,"Select a unique catalog component",VLOOKUP(A17,Components!$A$8:$F$107,6,FALSE))) | J17: =IF(OR(A17="",COUNTIF(Components!$A$8:$A$107,A17)<>1),"",IF(VLOOKUP(A17,Components!$A$8:$S$107,9,FALSE)="","",VLOOKUP(A17,Components!$A$8:$S$107,9,FALSE))) | K17: =IF(OR(A17="",COUNTIF(Components!$A$8:$A$107,A17)<>1),"",IF(VLOOKUP(A17,Components!$A$8:$S$107,10,FALSE)="","",VLOOKUP(A17,Components!$A$8:$S$107,10,FALSE))) | L17: =IF(OR(A17="",COUNTIF(Components!$A$8:$A$107,A17)<>1),"",IF(VLOOKUP(A17,Components!$A$8:$S$107,11,FALSE)="","",VLOOKUP(A17,Components!$A$8:$S$107,11,FALSE))) | M17: =IF(OR(A17="",COUNTIF(Components!$A$8:$A$107,A17)<>1),"",IF(VLOOKUP(A17,Components!$A$8:$S$107,12,FALSE)="","",VLOOKUP(A17,Components!$A$8:$S$107,12,FALSE))) | N17: =IF(OR(A17="",COUNTIF(Components!$A$8:$A$107,A17)<>1),"",IF(VLOOKUP(A17,Components!$A$8:$S$107,13,FALSE)="","",VLOOKUP(A17,Components!$A$8:$S$107,13,FALSE))) | O17: =IF(OR(N17="",NOT(ISNUMBER(B17))),"",B17*N17) | P17: =IF(OR(A17="",COUNTIF(Components!$A$8:$A$107,A17)<>1),"",IF(VLOOKUP(A17,Components!$A$8:$S$107,14,FALSE)="","",VLOOKUP(A17,Components!$A$8:$S$107,14,FALSE))) | Q17: =IF(OR(A17="",COUNTIF(Components!$A$8:$A$107,A17)<>1),"",IF(VLOOKUP(A17,Components!$A$8:$S$107,15,FALSE)="","",VLOOKUP(A17,Components!$A$8:$S$107,15,FALSE))) | R17: =IF(OR(A17="",COUNTIF(Components!$A$8:$A$107,A17)<>1),"",IF(VLOOKUP(A17,Components!$A$8:$S$107,16,FALSE)="","",VLOOKUP(A17,Components!$A$8:$S$107,16,FALSE))) | S17: =IF(OR(A17="",COUNTIF(Components!$A$8:$A$107,A17)<>1),"",IF(VLOOKUP(A17,Components!$A$8:$S$107,17,FALSE)="","",VLOOKUP(A17,Components!$A$8:$S$107,17,FALSE))) | T17: =IF(OR(A17="",COUNTIF(Components!$A$8:$A$107,A17)<>1),"",IF(VLOOKUP(A17,Components!$A$8:$S$107,18,FALSE)="","",VLOOKUP(A17,Components!$A$8:$S$107,18,FALSE))) | U17: =IF(OR(T17="",NOT(ISNUMBER(B17))),"",B17*T17)
C18: =IF(A18="","",IF(COUNTIF(Components!$A$8:$A$107,A18)<>1,"Pending",VLOOKUP(A18,Components!$A$8:$F$107,5,FALSE))) | E18: =IF(A18="","",IF(ISBLANK(D18),C18,IF(AND(ISNUMBER(D18),D18>=0),D18,"Pending"))) | F18: =IF(OR(G18="Catalog basis",G18="Override used"),B18*E18,"") | G18: =IF(A18="",IF(OR(NOT(ISBLANK(B18)),NOT(ISBLANK(D18))),"Needs component",""),IF(COUNTIF(Components!$A$8:$A$107,A18)<>1,"Invalid component",IF(ISBLANK(B18),"Needs quantity",IF(NOT(ISNUMBER(B18)),"Invalid quantity",IF(OR(B18<0,B18<>INT(B18)),"Invalid quantity",IF(NOT(ISNUMBER(E18)),"Needs heat input",IF(NOT(ISBLANK(D18)),"Override used","Catalog basis"))))))) | I18: =IF(A18="","",IF(COUNTIF(Components!$A$8:$A$107,A18)<>1,"Select a unique catalog component",VLOOKUP(A18,Components!$A$8:$F$107,6,FALSE))) | J18: =IF(OR(A18="",COUNTIF(Components!$A$8:$A$107,A18)<>1),"",IF(VLOOKUP(A18,Components!$A$8:$S$107,9,FALSE)="","",VLOOKUP(A18,Components!$A$8:$S$107,9,FALSE))) | K18: =IF(OR(A18="",COUNTIF(Components!$A$8:$A$107,A18)<>1),"",IF(VLOOKUP(A18,Components!$A$8:$S$107,10,FALSE)="","",VLOOKUP(A18,Components!$A$8:$S$107,10,FALSE))) | L18: =IF(OR(A18="",COUNTIF(Components!$A$8:$A$107,A18)<>1),"",IF(VLOOKUP(A18,Components!$A$8:$S$107,11,FALSE)="","",VLOOKUP(A18,Components!$A$8:$S$107,11,FALSE))) | M18: =IF(OR(A18="",COUNTIF(Components!$A$8:$A$107,A18)<>1),"",IF(VLOOKUP(A18,Components!$A$8:$S$107,12,FALSE)="","",VLOOKUP(A18,Components!$A$8:$S$107,12,FALSE))) | N18: =IF(OR(A18="",COUNTIF(Components!$A$8:$A$107,A18)<>1),"",IF(VLOOKUP(A18,Components!$A$8:$S$107,13,FALSE)="","",VLOOKUP(A18,Components!$A$8:$S$107,13,FALSE))) | O18: =IF(OR(N18="",NOT(ISNUMBER(B18))),"",B18*N18) | P18: =IF(OR(A18="",COUNTIF(Components!$A$8:$A$107,A18)<>1),"",IF(VLOOKUP(A18,Components!$A$8:$S$107,14,FALSE)="","",VLOOKUP(A18,Components!$A$8:$S$107,14,FALSE))) | Q18: =IF(OR(A18="",COUNTIF(Components!$A$8:$A$107,A18)<>1),"",IF(VLOOKUP(A18,Components!$A$8:$S$107,15,FALSE)="","",VLOOKUP(A18,Components!$A$8:$S$107,15,FALSE))) | R18: =IF(OR(A18="",COUNTIF(Components!$A$8:$A$107,A18)<>1),"",IF(VLOOKUP(A18,Components!$A$8:$S$107,16,FALSE)="","",VLOOKUP(A18,Components!$A$8:$S$107,16,FALSE))) | S18: =IF(OR(A18="",COUNTIF(Components!$A$8:$A$107,A18)<>1),"",IF(VLOOKUP(A18,Components!$A$8:$S$107,17,FALSE)="","",VLOOKUP(A18,Components!$A$8:$S$107,17,FALSE))) | T18: =IF(OR(A18="",COUNTIF(Components!$A$8:$A$107,A18)<>1),"",IF(VLOOKUP(A18,Components!$A$8:$S$107,18,FALSE)="","",VLOOKUP(A18,Components!$A$8:$S$107,18,FALSE))) | U18: =IF(OR(T18="",NOT(ISNUMBER(B18))),"",B18*T18)
C19: =IF(A19="","",IF(COUNTIF(Components!$A$8:$A$107,A19)<>1,"Pending",VLOOKUP(A19,Components!$A$8:$F$107,5,FALSE))) | E19: =IF(A19="","",IF(ISBLANK(D19),C19,IF(AND(ISNUMBER(D19),D19>=0),D19,"Pending"))) | F19: =IF(OR(G19="Catalog basis",G19="Override used"),B19*E19,"") | G19: =IF(A19="",IF(OR(NOT(ISBLANK(B19)),NOT(ISBLANK(D19))),"Needs component",""),IF(COUNTIF(Components!$A$8:$A$107,A19)<>1,"Invalid component",IF(ISBLANK(B19),"Needs quantity",IF(NOT(ISNUMBER(B19)),"Invalid quantity",IF(OR(B19<0,B19<>INT(B19)),"Invalid quantity",IF(NOT(ISNUMBER(E19)),"Needs heat input",IF(NOT(ISBLANK(D19)),"Override used","Catalog basis"))))))) | I19: =IF(A19="","",IF(COUNTIF(Components!$A$8:$A$107,A19)<>1,"Select a unique catalog component",VLOOKUP(A19,Components!$A$8:$F$107,6,FALSE))) | J19: =IF(OR(A19="",COUNTIF(Components!$A$8:$A$107,A19)<>1),"",IF(VLOOKUP(A19,Components!$A$8:$S$107,9,FALSE)="","",VLOOKUP(A19,Components!$A$8:$S$107,9,FALSE))) | K19: =IF(OR(A19="",COUNTIF(Components!$A$8:$A$107,A19)<>1),"",IF(VLOOKUP(A19,Components!$A$8:$S$107,10,FALSE)="","",VLOOKUP(A19,Components!$A$8:$S$107,10,FALSE))) | L19: =IF(OR(A19="",COUNTIF(Components!$A$8:$A$107,A19)<>1),"",IF(VLOOKUP(A19,Components!$A$8:$S$107,11,FALSE)="","",VLOOKUP(A19,Components!$A$8:$S$107,11,FALSE))) | M19: =IF(OR(A19="",COUNTIF(Components!$A$8:$A$107,A19)<>1),"",IF(VLOOKUP(A19,Components!$A$8:$S$107,12,FALSE)="","",VLOOKUP(A19,Components!$A$8:$S$107,12,FALSE))) | N19: =IF(OR(A19="",COUNTIF(Components!$A$8:$A$107,A19)<>1),"",IF(VLOOKUP(A19,Components!$A$8:$S$107,13,FALSE)="","",VLOOKUP(A19,Components!$A$8:$S$107,13,FALSE))) | O19: =IF(OR(N19="",NOT(ISNUMBER(B19))),"",B19*N19) | P19: =IF(OR(A19="",COUNTIF(Components!$A$8:$A$107,A19)<>1),"",IF(VLOOKUP(A19,Components!$A$8:$S$107,14,FALSE)="","",VLOOKUP(A19,Components!$A$8:$S$107,14,FALSE))) | Q19: =IF(OR(A19="",COUNTIF(Components!$A$8:$A$107,A19)<>1),"",IF(VLOOKUP(A19,Components!$A$8:$S$107,15,FALSE)="","",VLOOKUP(A19,Components!$A$8:$S$107,15,FALSE))) | R19: =IF(OR(A19="",COUNTIF(Components!$A$8:$A$107,A19)<>1),"",IF(VLOOKUP(A19,Components!$A$8:$S$107,16,FALSE)="","",VLOOKUP(A19,Components!$A$8:$S$107,16,FALSE))) | S19: =IF(OR(A19="",COUNTIF(Components!$A$8:$A$107,A19)<>1),"",IF(VLOOKUP(A19,Components!$A$8:$S$107,17,FALSE)="","",VLOOKUP(A19,Components!$A$8:$S$107,17,FALSE))) | T19: =IF(OR(A19="",COUNTIF(Components!$A$8:$A$107,A19)<>1),"",IF(VLOOKUP(A19,Components!$A$8:$S$107,18,FALSE)="","",VLOOKUP(A19,Components!$A$8:$S$107,18,FALSE))) | U19: =IF(OR(T19="",NOT(ISNUMBER(B19))),"",B19*T19)
C20: =IF(A20="","",IF(COUNTIF(Components!$A$8:$A$107,A20)<>1,"Pending",VLOOKUP(A20,Components!$A$8:$F$107,5,FALSE))) | E20: =IF(A20="","",IF(ISBLANK(D20),C20,IF(AND(ISNUMBER(D20),D20>=0),D20,"Pending"))) | F20: =IF(OR(G20="Catalog basis",G20="Override used"),B20*E20,"") | G20: =IF(A20="",IF(OR(NOT(ISBLANK(B20)),NOT(ISBLANK(D20))),"Needs component",""),IF(COUNTIF(Components!$A$8:$A$107,A20)<>1,"Invalid component",IF(ISBLANK(B20),"Needs quantity",IF(NOT(ISNUMBER(B20)),"Invalid quantity",IF(OR(B20<0,B20<>INT(B20)),"Invalid quantity",IF(NOT(ISNUMBER(E20)),"Needs heat input",IF(NOT(ISBLANK(D20)),"Override used","Catalog basis"))))))) | I20: =IF(A20="","",IF(COUNTIF(Components!$A$8:$A$107,A20)<>1,"Select a unique catalog component",VLOOKUP(A20,Components!$A$8:$F$107,6,FALSE))) | J20: =IF(OR(A20="",COUNTIF(Components!$A$8:$A$107,A20)<>1),"",IF(VLOOKUP(A20,Components!$A$8:$S$107,9,FALSE)="","",VLOOKUP(A20,Components!$A$8:$S$107,9,FALSE))) | K20: =IF(OR(A20="",COUNTIF(Components!$A$8:$A$107,A20)<>1),"",IF(VLOOKUP(A20,Components!$A$8:$S$107,10,FALSE)="","",VLOOKUP(A20,Components!$A$8:$S$107,10,FALSE))) | L20: =IF(OR(A20="",COUNTIF(Components!$A$8:$A$107,A20)<>1),"",IF(VLOOKUP(A20,Components!$A$8:$S$107,11,FALSE)="","",VLOOKUP(A20,Components!$A$8:$S$107,11,FALSE))) | M20: =IF(OR(A20="",COUNTIF(Components!$A$8:$A$107,A20)<>1),"",IF(VLOOKUP(A20,Components!$A$8:$S$107,12,FALSE)="","",VLOOKUP(A20,Components!$A$8:$S$107,12,FALSE))) | N20: =IF(OR(A20="",COUNTIF(Components!$A$8:$A$107,A20)<>1),"",IF(VLOOKUP(A20,Components!$A$8:$S$107,13,FALSE)="","",VLOOKUP(A20,Components!$A$8:$S$107,13,FALSE))) | O20: =IF(OR(N20="",NOT(ISNUMBER(B20))),"",B20*N20) | P20: =IF(OR(A20="",COUNTIF(Components!$A$8:$A$107,A20)<>1),"",IF(VLOOKUP(A20,Components!$A$8:$S$107,14,FALSE)="","",VLOOKUP(A20,Components!$A$8:$S$107,14,FALSE))) | Q20: =IF(OR(A20="",COUNTIF(Components!$A$8:$A$107,A20)<>1),"",IF(VLOOKUP(A20,Components!$A$8:$S$107,15,FALSE)="","",VLOOKUP(A20,Components!$A$8:$S$107,15,FALSE))) | R20: =IF(OR(A20="",COUNTIF(Components!$A$8:$A$107,A20)<>1),"",IF(VLOOKUP(A20,Components!$A$8:$S$107,16,FALSE)="","",VLOOKUP(A20,Components!$A$8:$S$107,16,FALSE))) | S20: =IF(OR(A20="",COUNTIF(Components!$A$8:$A$107,A20)<>1),"",IF(VLOOKUP(A20,Components!$A$8:$S$107,17,FALSE)="","",VLOOKUP(A20,Components!$A$8:$S$107,17,FALSE))) | T20: =IF(OR(A20="",COUNTIF(Components!$A$8:$A$107,A20)<>1),"",IF(VLOOKUP(A20,Components!$A$8:$S$107,18,FALSE)="","",VLOOKUP(A20,Components!$A$8:$S$107,18,FALSE))) | U20: =IF(OR(T20="",NOT(ISNUMBER(B20))),"",B20*T20)
C21: =IF(A21="","",IF(COUNTIF(Components!$A$8:$A$107,A21)<>1,"Pending",VLOOKUP(A21,Components!$A$8:$F$107,5,FALSE))) | E21: =IF(A21="","",IF(ISBLANK(D21),C21,IF(AND(ISNUMBER(D21),D21>=0),D21,"Pending"))) | F21: =IF(OR(G21="Catalog basis",G21="Override used"),B21*E21,"") | G21: =IF(A21="",IF(OR(NOT(ISBLANK(B21)),NOT(ISBLANK(D21))),"Needs component",""),IF(COUNTIF(Components!$A$8:$A$107,A21)<>1,"Invalid component",IF(ISBLANK(B21),"Needs quantity",IF(NOT(ISNUMBER(B21)),"Invalid quantity",IF(OR(B21<0,B21<>INT(B21)),"Invalid quantity",IF(NOT(ISNUMBER(E21)),"Needs heat input",IF(NOT(ISBLANK(D21)),"Override used","Catalog basis"))))))) | I21: =IF(A21="","",IF(COUNTIF(Components!$A$8:$A$107,A21)<>1,"Select a unique catalog component",VLOOKUP(A21,Components!$A$8:$F$107,6,FALSE))) | J21: =IF(OR(A21="",COUNTIF(Components!$A$8:$A$107,A21)<>1),"",IF(VLOOKUP(A21,Components!$A$8:$S$107,9,FALSE)="","",VLOOKUP(A21,Components!$A$8:$S$107,9,FALSE))) | K21: =IF(OR(A21="",COUNTIF(Components!$A$8:$A$107,A21)<>1),"",IF(VLOOKUP(A21,Components!$A$8:$S$107,10,FALSE)="","",VLOOKUP(A21,Components!$A$8:$S$107,10,FALSE))) | L21: =IF(OR(A21="",COUNTIF(Components!$A$8:$A$107,A21)<>1),"",IF(VLOOKUP(A21,Components!$A$8:$S$107,11,FALSE)="","",VLOOKUP(A21,Components!$A$8:$S$107,11,FALSE))) | M21: =IF(OR(A21="",COUNTIF(Components!$A$8:$A$107,A21)<>1),"",IF(VLOOKUP(A21,Components!$A$8:$S$107,12,FALSE)="","",VLOOKUP(A21,Components!$A$8:$S$107,12,FALSE))) | N21: =IF(OR(A21="",COUNTIF(Components!$A$8:$A$107,A21)<>1),"",IF(VLOOKUP(A21,Components!$A$8:$S$107,13,FALSE)="","",VLOOKUP(A21,Components!$A$8:$S$107,13,FALSE))) | O21: =IF(OR(N21="",NOT(ISNUMBER(B21))),"",B21*N21) | P21: =IF(OR(A21="",COUNTIF(Components!$A$8:$A$107,A21)<>1),"",IF(VLOOKUP(A21,Components!$A$8:$S$107,14,FALSE)="","",VLOOKUP(A21,Components!$A$8:$S$107,14,FALSE))) | Q21: =IF(OR(A21="",COUNTIF(Components!$A$8:$A$107,A21)<>1),"",IF(VLOOKUP(A21,Components!$A$8:$S$107,15,FALSE)="","",VLOOKUP(A21,Components!$A$8:$S$107,15,FALSE))) | R21: =IF(OR(A21="",COUNTIF(Components!$A$8:$A$107,A21)<>1),"",IF(VLOOKUP(A21,Components!$A$8:$S$107,16,FALSE)="","",VLOOKUP(A21,Components!$A$8:$S$107,16,FALSE))) | S21: =IF(OR(A21="",COUNTIF(Components!$A$8:$A$107,A21)<>1),"",IF(VLOOKUP(A21,Components!$A$8:$S$107,17,FALSE)="","",VLOOKUP(A21,Components!$A$8:$S$107,17,FALSE))) | T21: =IF(OR(A21="",COUNTIF(Components!$A$8:$A$107,A21)<>1),"",IF(VLOOKUP(A21,Components!$A$8:$S$107,18,FALSE)="","",VLOOKUP(A21,Components!$A$8:$S$107,18,FALSE))) | U21: =IF(OR(T21="",NOT(ISNUMBER(B21))),"",B21*T21)
C22: =IF(A22="","",IF(COUNTIF(Components!$A$8:$A$107,A22)<>1,"Pending",VLOOKUP(A22,Components!$A$8:$F$107,5,FALSE))) | E22: =IF(A22="","",IF(ISBLANK(D22),C22,IF(AND(ISNUMBER(D22),D22>=0),D22,"Pending"))) | F22: =IF(OR(G22="Catalog basis",G22="Override used"),B22*E22,"") | G22: =IF(A22="",IF(OR(NOT(ISBLANK(B22)),NOT(ISBLANK(D22))),"Needs component",""),IF(COUNTIF(Components!$A$8:$A$107,A22)<>1,"Invalid component",IF(ISBLANK(B22),"Needs quantity",IF(NOT(ISNUMBER(B22)),"Invalid quantity",IF(OR(B22<0,B22<>INT(B22)),"Invalid quantity",IF(NOT(ISNUMBER(E22)),"Needs heat input",IF(NOT(ISBLANK(D22)),"Override used","Catalog basis"))))))) | I22: =IF(A22="","",IF(COUNTIF(Components!$A$8:$A$107,A22)<>1,"Select a unique catalog component",VLOOKUP(A22,Components!$A$8:$F$107,6,FALSE))) | J22: =IF(OR(A22="",COUNTIF(Components!$A$8:$A$107,A22)<>1),"",IF(VLOOKUP(A22,Components!$A$8:$S$107,9,FALSE)="","",VLOOKUP(A22,Components!$A$8:$S$107,9,FALSE))) | K22: =IF(OR(A22="",COUNTIF(Components!$A$8:$A$107,A22)<>1),"",IF(VLOOKUP(A22,Components!$A$8:$S$107,10,FALSE)="","",VLOOKUP(A22,Components!$A$8:$S$107,10,FALSE))) | L22: =IF(OR(A22="",COUNTIF(Components!$A$8:$A$107,A22)<>1),"",IF(VLOOKUP(A22,Components!$A$8:$S$107,11,FALSE)="","",VLOOKUP(A22,Components!$A$8:$S$107,11,FALSE))) | M22: =IF(OR(A22="",COUNTIF(Components!$A$8:$A$107,A22)<>1),"",IF(VLOOKUP(A22,Components!$A$8:$S$107,12,FALSE)="","",VLOOKUP(A22,Components!$A$8:$S$107,12,FALSE))) | N22: =IF(OR(A22="",COUNTIF(Components!$A$8:$A$107,A22)<>1),"",IF(VLOOKUP(A22,Components!$A$8:$S$107,13,FALSE)="","",VLOOKUP(A22,Components!$A$8:$S$107,13,FALSE))) | O22: =IF(OR(N22="",NOT(ISNUMBER(B22))),"",B22*N22) | P22: =IF(OR(A22="",COUNTIF(Components!$A$8:$A$107,A22)<>1),"",IF(VLOOKUP(A22,Components!$A$8:$S$107,14,FALSE)="","",VLOOKUP(A22,Components!$A$8:$S$107,14,FALSE))) | Q22: =IF(OR(A22="",COUNTIF(Components!$A$8:$A$107,A22)<>1),"",IF(VLOOKUP(A22,Components!$A$8:$S$107,15,FALSE)="","",VLOOKUP(A22,Components!$A$8:$S$107,15,FALSE))) | R22: =IF(OR(A22="",COUNTIF(Components!$A$8:$A$107,A22)<>1),"",IF(VLOOKUP(A22,Components!$A$8:$S$107,16,FALSE)="","",VLOOKUP(A22,Components!$A$8:$S$107,16,FALSE))) | S22: =IF(OR(A22="",COUNTIF(Components!$A$8:$A$107,A22)<>1),"",IF(VLOOKUP(A22,Components!$A$8:$S$107,17,FALSE)="","",VLOOKUP(A22,Components!$A$8:$S$107,17,FALSE))) | T22: =IF(OR(A22="",COUNTIF(Components!$A$8:$A$107,A22)<>1),"",IF(VLOOKUP(A22,Components!$A$8:$S$107,18,FALSE)="","",VLOOKUP(A22,Components!$A$8:$S$107,18,FALSE))) | U22: =IF(OR(T22="",NOT(ISNUMBER(B22))),"",B22*T22)
C23: =IF(A23="","",IF(COUNTIF(Components!$A$8:$A$107,A23)<>1,"Pending",VLOOKUP(A23,Components!$A$8:$F$107,5,FALSE))) | E23: =IF(A23="","",IF(ISBLANK(D23),C23,IF(AND(ISNUMBER(D23),D23>=0),D23,"Pending"))) | F23: =IF(OR(G23="Catalog basis",G23="Override used"),B23*E23,"") | G23: =IF(A23="",IF(OR(NOT(ISBLANK(B23)),NOT(ISBLANK(D23))),"Needs component",""),IF(COUNTIF(Components!$A$8:$A$107,A23)<>1,"Invalid component",IF(ISBLANK(B23),"Needs quantity",IF(NOT(ISNUMBER(B23)),"Invalid quantity",IF(OR(B23<0,B23<>INT(B23)),"Invalid quantity",IF(NOT(ISNUMBER(E23)),"Needs heat input",IF(NOT(ISBLANK(D23)),"Override used","Catalog basis"))))))) | I23: =IF(A23="","",IF(COUNTIF(Components!$A$8:$A$107,A23)<>1,"Select a unique catalog component",VLOOKUP(A23,Components!$A$8:$F$107,6,FALSE))) | J23: =IF(OR(A23="",COUNTIF(Components!$A$8:$A$107,A23)<>1),"",IF(VLOOKUP(A23,Components!$A$8:$S$107,9,FALSE)="","",VLOOKUP(A23,Components!$A$8:$S$107,9,FALSE))) | K23: =IF(OR(A23="",COUNTIF(Components!$A$8:$A$107,A23)<>1),"",IF(VLOOKUP(A23,Components!$A$8:$S$107,10,FALSE)="","",VLOOKUP(A23,Components!$A$8:$S$107,10,FALSE))) | L23: =IF(OR(A23="",COUNTIF(Components!$A$8:$A$107,A23)<>1),"",IF(VLOOKUP(A23,Components!$A$8:$S$107,11,FALSE)="","",VLOOKUP(A23,Components!$A$8:$S$107,11,FALSE))) | M23: =IF(OR(A23="",COUNTIF(Components!$A$8:$A$107,A23)<>1),"",IF(VLOOKUP(A23,Components!$A$8:$S$107,12,FALSE)="","",VLOOKUP(A23,Components!$A$8:$S$107,12,FALSE))) | N23: =IF(OR(A23="",COUNTIF(Components!$A$8:$A$107,A23)<>1),"",IF(VLOOKUP(A23,Components!$A$8:$S$107,13,FALSE)="","",VLOOKUP(A23,Components!$A$8:$S$107,13,FALSE))) | O23: =IF(OR(N23="",NOT(ISNUMBER(B23))),"",B23*N23) | P23: =IF(OR(A23="",COUNTIF(Components!$A$8:$A$107,A23)<>1),"",IF(VLOOKUP(A23,Components!$A$8:$S$107,14,FALSE)="","",VLOOKUP(A23,Components!$A$8:$S$107,14,FALSE))) | Q23: =IF(OR(A23="",COUNTIF(Components!$A$8:$A$107,A23)<>1),"",IF(VLOOKUP(A23,Components!$A$8:$S$107,15,FALSE)="","",VLOOKUP(A23,Components!$A$8:$S$107,15,FALSE))) | R23: =IF(OR(A23="",COUNTIF(Components!$A$8:$A$107,A23)<>1),"",IF(VLOOKUP(A23,Components!$A$8:$S$107,16,FALSE)="","",VLOOKUP(A23,Components!$A$8:$S$107,16,FALSE))) | S23: =IF(OR(A23="",COUNTIF(Components!$A$8:$A$107,A23)<>1),"",IF(VLOOKUP(A23,Components!$A$8:$S$107,17,FALSE)="","",VLOOKUP(A23,Components!$A$8:$S$107,17,FALSE))) | T23: =IF(OR(A23="",COUNTIF(Components!$A$8:$A$107,A23)<>1),"",IF(VLOOKUP(A23,Components!$A$8:$S$107,18,FALSE)="","",VLOOKUP(A23,Components!$A$8:$S$107,18,FALSE))) | U23: =IF(OR(T23="",NOT(ISNUMBER(B23))),"",B23*T23)
C24: =IF(A24="","",IF(COUNTIF(Components!$A$8:$A$107,A24)<>1,"Pending",VLOOKUP(A24,Components!$A$8:$F$107,5,FALSE))) | E24: =IF(A24="","",IF(ISBLANK(D24),C24,IF(AND(ISNUMBER(D24),D24>=0),D24,"Pending"))) | F24: =IF(OR(G24="Catalog basis",G24="Override used"),B24*E24,"") | G24: =IF(A24="",IF(OR(NOT(ISBLANK(B24)),NOT(ISBLANK(D24))),"Needs component",""),IF(COUNTIF(Components!$A$8:$A$107,A24)<>1,"Invalid component",IF(ISBLANK(B24),"Needs quantity",IF(NOT(ISNUMBER(B24)),"Invalid quantity",IF(OR(B24<0,B24<>INT(B24)),"Invalid quantity",IF(NOT(ISNUMBER(E24)),"Needs heat input",IF(NOT(ISBLANK(D24)),"Override used","Catalog basis"))))))) | I24: =IF(A24="","",IF(COUNTIF(Components!$A$8:$A$107,A24)<>1,"Select a unique catalog component",VLOOKUP(A24,Components!$A$8:$F$107,6,FALSE))) | J24: =IF(OR(A24="",COUNTIF(Components!$A$8:$A$107,A24)<>1),"",IF(VLOOKUP(A24,Components!$A$8:$S$107,9,FALSE)="","",VLOOKUP(A24,Components!$A$8:$S$107,9,FALSE))) | K24: =IF(OR(A24="",COUNTIF(Components!$A$8:$A$107,A24)<>1),"",IF(VLOOKUP(A24,Components!$A$8:$S$107,10,FALSE)="","",VLOOKUP(A24,Components!$A$8:$S$107,10,FALSE))) | L24: =IF(OR(A24="",COUNTIF(Components!$A$8:$A$107,A24)<>1),"",IF(VLOOKUP(A24,Components!$A$8:$S$107,11,FALSE)="","",VLOOKUP(A24,Components!$A$8:$S$107,11,FALSE))) | M24: =IF(OR(A24="",COUNTIF(Components!$A$8:$A$107,A24)<>1),"",IF(VLOOKUP(A24,Components!$A$8:$S$107,12,FALSE)="","",VLOOKUP(A24,Components!$A$8:$S$107,12,FALSE))) | N24: =IF(OR(A24="",COUNTIF(Components!$A$8:$A$107,A24)<>1),"",IF(VLOOKUP(A24,Components!$A$8:$S$107,13,FALSE)="","",VLOOKUP(A24,Components!$A$8:$S$107,13,FALSE))) | O24: =IF(OR(N24="",NOT(ISNUMBER(B24))),"",B24*N24) | P24: =IF(OR(A24="",COUNTIF(Components!$A$8:$A$107,A24)<>1),"",IF(VLOOKUP(A24,Components!$A$8:$S$107,14,FALSE)="","",VLOOKUP(A24,Components!$A$8:$S$107,14,FALSE))) | Q24: =IF(OR(A24="",COUNTIF(Components!$A$8:$A$107,A24)<>1),"",IF(VLOOKUP(A24,Components!$A$8:$S$107,15,FALSE)="","",VLOOKUP(A24,Components!$A$8:$S$107,15,FALSE))) | R24: =IF(OR(A24="",COUNTIF(Components!$A$8:$A$107,A24)<>1),"",IF(VLOOKUP(A24,Components!$A$8:$S$107,16,FALSE)="","",VLOOKUP(A24,Components!$A$8:$S$107,16,FALSE))) | S24: =IF(OR(A24="",COUNTIF(Components!$A$8:$A$107,A24)<>1),"",IF(VLOOKUP(A24,Components!$A$8:$S$107,17,FALSE)="","",VLOOKUP(A24,Components!$A$8:$S$107,17,FALSE))) | T24: =IF(OR(A24="",COUNTIF(Components!$A$8:$A$107,A24)<>1),"",IF(VLOOKUP(A24,Components!$A$8:$S$107,18,FALSE)="","",VLOOKUP(A24,Components!$A$8:$S$107,18,FALSE))) | U24: =IF(OR(T24="",NOT(ISNUMBER(B24))),"",B24*T24)
C25: =IF(A25="","",IF(COUNTIF(Components!$A$8:$A$107,A25)<>1,"Pending",VLOOKUP(A25,Components!$A$8:$F$107,5,FALSE))) | E25: =IF(A25="","",IF(ISBLANK(D25),C25,IF(AND(ISNUMBER(D25),D25>=0),D25,"Pending"))) | F25: =IF(OR(G25="Catalog basis",G25="Override used"),B25*E25,"") | G25: =IF(A25="",IF(OR(NOT(ISBLANK(B25)),NOT(ISBLANK(D25))),"Needs component",""),IF(COUNTIF(Components!$A$8:$A$107,A25)<>1,"Invalid component",IF(ISBLANK(B25),"Needs quantity",IF(NOT(ISNUMBER(B25)),"Invalid quantity",IF(OR(B25<0,B25<>INT(B25)),"Invalid quantity",IF(NOT(ISNUMBER(E25)),"Needs heat input",IF(NOT(ISBLANK(D25)),"Override used","Catalog basis"))))))) | I25: =IF(A25="","",IF(COUNTIF(Components!$A$8:$A$107,A25)<>1,"Select a unique catalog component",VLOOKUP(A25,Components!$A$8:$F$107,6,FALSE))) | J25: =IF(OR(A25="",COUNTIF(Components!$A$8:$A$107,A25)<>1),"",IF(VLOOKUP(A25,Components!$A$8:$S$107,9,FALSE)="","",VLOOKUP(A25,Components!$A$8:$S$107,9,FALSE))) | K25: =IF(OR(A25="",COUNTIF(Components!$A$8:$A$107,A25)<>1),"",IF(VLOOKUP(A25,Components!$A$8:$S$107,10,FALSE)="","",VLOOKUP(A25,Components!$A$8:$S$107,10,FALSE))) | L25: =IF(OR(A25="",COUNTIF(Components!$A$8:$A$107,A25)<>1),"",IF(VLOOKUP(A25,Components!$A$8:$S$107,11,FALSE)="","",VLOOKUP(A25,Components!$A$8:$S$107,11,FALSE))) | M25: =IF(OR(A25="",COUNTIF(Components!$A$8:$A$107,A25)<>1),"",IF(VLOOKUP(A25,Components!$A$8:$S$107,12,FALSE)="","",VLOOKUP(A25,Components!$A$8:$S$107,12,FALSE))) | N25: =IF(OR(A25="",COUNTIF(Components!$A$8:$A$107,A25)<>1),"",IF(VLOOKUP(A25,Components!$A$8:$S$107,13,FALSE)="","",VLOOKUP(A25,Components!$A$8:$S$107,13,FALSE))) | O25: =IF(OR(N25="",NOT(ISNUMBER(B25))),"",B25*N25) | P25: =IF(OR(A25="",COUNTIF(Components!$A$8:$A$107,A25)<>1),"",IF(VLOOKUP(A25,Components!$A$8:$S$107,14,FALSE)="","",VLOOKUP(A25,Components!$A$8:$S$107,14,FALSE))) | Q25: =IF(OR(A25="",COUNTIF(Components!$A$8:$A$107,A25)<>1),"",IF(VLOOKUP(A25,Components!$A$8:$S$107,15,FALSE)="","",VLOOKUP(A25,Components!$A$8:$S$107,15,FALSE))) | R25: =IF(OR(A25="",COUNTIF(Components!$A$8:$A$107,A25)<>1),"",IF(VLOOKUP(A25,Components!$A$8:$S$107,16,FALSE)="","",VLOOKUP(A25,Components!$A$8:$S$107,16,FALSE))) | S25: =IF(OR(A25="",COUNTIF(Components!$A$8:$A$107,A25)<>1),"",IF(VLOOKUP(A25,Components!$A$8:$S$107,17,FALSE)="","",VLOOKUP(A25,Components!$A$8:$S$107,17,FALSE))) | T25: =IF(OR(A25="",COUNTIF(Components!$A$8:$A$107,A25)<>1),"",IF(VLOOKUP(A25,Components!$A$8:$S$107,18,FALSE)="","",VLOOKUP(A25,Components!$A$8:$S$107,18,FALSE))) | U25: =IF(OR(T25="",NOT(ISNUMBER(B25))),"",B25*T25)
... C70: =IF(A70="","",IF(COUNTIF(Components!$A$8:$A$107,A70)<>1,"Pending",VLOOKUP(A70,Components!$A$8:$F$107,5,FALSE))) | E70: =IF(A70="","",IF(ISBLANK(D70),C70,IF(AND(ISNUMBER(D70),D70>=0),D70,"Pending"))) | F70: =IF(OR(G70="Catalog basis",G70="Override used"),B70*E70,"") | G70: =IF(A70="",IF(OR(NOT(ISBLANK(B70)),NOT(ISBLANK(D70))),"Needs component",""),IF(COUNTIF(Components!$A$8:$A$107,A70)<>1,"Invalid component",IF(ISBLANK(B70),"Needs quantity",IF(NOT(ISNUMBER(B70)),"Invalid quantity",IF(OR(B70<0,B70<>INT(B70)),"Invalid quantity",IF(NOT(ISNUMBER(E70)),"Needs heat input",IF(NOT(ISBLANK(D70)),"Override used","Catalog basis"))))))) | I70: =IF(A70="","",IF(COUNTIF(Components!$A$8:$A$107,A70)<>1,"Select a unique catalog component",VLOOKUP(A70,Components!$A$8:$F$107,6,FALSE))) | J70: =IF(OR(A70="",COUNTIF(Components!$A$8:$A$107,A70)<>1),"",IF(VLOOKUP(A70,Components!$A$8:$S$107,9,FALSE)="","",VLOOKUP(A70,Components!$A$8:$S$107,9,FALSE))) | K70: =IF(OR(A70="",COUNTIF(Components!$A$8:$A$107,A70)<>1),"",IF(VLOOKUP(A70,Components!$A$8:$S$107,10,FALSE)="","",VLOOKUP(A70,Components!$A$8:$S$107,10,FALSE))) | L70: =IF(OR(A70="",COUNTIF(Components!$A$8:$A$107,A70)<>1),"",IF(VLOOKUP(A70,Components!$A$8:$S$107,11,FALSE)="","",VLOOKUP(A70,Components!$A$8:$S$107,11,FALSE))) | M70: =IF(OR(A70="",COUNTIF(Components!$A$8:$A$107,A70)<>1),"",IF(VLOOKUP(A70,Components!$A$8:$S$107,12,FALSE)="","",VLOOKUP(A70,Components!$A$8:$S$107,12,FALSE))) | N70: =IF(OR(A70="",COUNTIF(Components!$A$8:$A$107,A70)<>1),"",IF(VLOOKUP(A70,Components!$A$8:$S$107,13,FALSE)="","",VLOOKUP(A70,Components!$A$8:$S$107,13,FALSE))) | O70: =IF(OR(N70="",NOT(ISNUMBER(B70))),"",B70*N70) | P70: =IF(OR(A70="",COUNTIF(Components!$A$8:$A$107,A70)<>1),"",IF(VLOOKUP(A70,Components!$A$8:$S$107,14,FALSE)="","",VLOOKUP(A70,Components!$A$8:$S$107,14,FALSE))) | Q70: =IF(OR(A70="",COUNTIF(Components!$A$8:$A$107,A70)<>1),"",IF(VLOOKUP(A70,Components!$A$8:$S$107,15,FALSE)="","",VLOOKUP(A70,Components!$A$8:$S$107,15,FALSE))) | R70: =IF(OR(A70="",COUNTIF(Components!$A$8:$A$107,A70)<>1),"",IF(VLOOKUP(A70,Components!$A$8:$S$107,16,FALSE)="","",VLOOKUP(A70,Components!$A$8:$S$107,16,FALSE))) | S70: =IF(OR(A70="",COUNTIF(Components!$A$8:$A$107,A70)<>1),"",IF(VLOOKUP(A70,Components!$A$8:$S$107,17,FALSE)="","",VLOOKUP(A70,Components!$A$8:$S$107,17,FALSE))) | T70: =IF(OR(A70="",COUNTIF(Components!$A$8:$A$107,A70)<>1),"",IF(VLOOKUP(A70,Components!$A$8:$S$107,18,FALSE)="","",VLOOKUP(A70,Components!$A$8:$S$107,18,FALSE))) | U70: =IF(OR(T70="",NOT(ISNUMBER(B70))),"",B70*T70)

Sheet Components
A2: Component heat catalog
A3: Amber cells are editable. Per-unit heat = DC heat + reference RF input x heat fraction.
A4: RF reference powers are examples or rated inputs, NOT verified system operating powers. Review before fan sizing.
A5: Add new unique part names in rows 8-107. Enclosure lists and lookups already cover these rows.
A7: Component / operating case | B7: DC heat W/unit | C7: Reference RF W/unit | D7: RF heat fraction | E7: Heat W/unit | F7: Basis / limitations | H7: Source | I7: Rail 1 voltage type | J7: Rail 1 V min | K7: Rail 1 V recommended | L7: Rail 1 V max | M7: Rail 1 max A | N7: Rail 2 voltage type | O7: Rail 2 V min | P7: Rail 2 V recommended | Q7: Rail 2 V max | R7: Rail 2 max A | S7: Electrical basis / notes
A8: MSP2TA-18-12+ (energized) | B8: 5.16 | C8: 0 | D8: 0.108749 | E8: =IF(A8="","",IF(COUNT(B8:D8)<3,"Pending",B8+C8*D8)) | F8: 12 V x 0.430 A; continuously energized. RF default 0 W; add through-path RF and absorbed isolated-port power if significant. | H8: MSP2TA-18-12+.pdf, p.2; 0.5 dB maximum through loss | I8: +12 V | J8: 11.5 | K8: 12 | L8: 12.5 | M8: 0.43 | S8: 12 V +/-0.5 V operating range; 430 mA max coil current (13 VDC absolute max).
A9: MSP2TA-18-12+ (de-energized) | B9: 0 | C9: 0 | D9: 0.108749 | E9: =IF(A9="","",IF(COUNT(B9:D9)<3,"Pending",B9+C9*D9)) | F9: Coil off. RF default 0 W; add RF loss / internal termination heat as applicable. | H9: MSP2TA-18-12+.pdf, p.2 | I9: +12 V | J9: 11.5 | K9: 12 | L9: 12.5 | M9: 0 | S9: Coil off: 0 A.
A10: ZFL-1000+ | B10: 1.575 | C10: 0 | D10: 0 | E10: =IF(A10="","",IF(COUNT(B10:D10)<3,"Pending",B10+C10*D10)) | F10: 15 V x 105 mA DC budget; RF output subtraction neglected. | H10: ZFL-1000+.pdf, p.1 | I10: +15 V | K10: 15 | L10: 17 | M10: 0.105 | S10: 15 V nominal, 105 mA max. No minimum specified (curves shown at 12-16 V); 17 V is the absolute-maximum rating.
A11: ZVA-443X+ | B11: 0.75 | C11: 0 | D11: 0 | E11: =IF(A11="","",IF(COUNT(B11:D11)<3,"Pending",B11+C11*D11)) | F11: 5 V x 150 mA maximum current; DC heat budget, RF output subtraction neglected. | H11: ZVA-443X+.pdf, p.2 | I11: +5 V | K11: 5 | L11: 6 | M11: 0.15 | S11: +5.0 V test condition, 150 mA max. No minimum specified; 6 V is the absolute-maximum rating.
A12: ZX76-31A-PNS+ | B12: 0.010944 | C12: 0.25118864 | D12: 1 | E12: =IF(A12="","",IF(COUNT(B12:D12)<3,"Pending",B12+C12*D12)) | F12: Maximum supply voltages/currents; assumes all +24 dBm RF input absorbed at high attenuation. Control-driver heat separate. | H12: ZX76-31A-PNS+.pdf, pp.2-3 | I12: +3 V | J12: 2.7 | K12: 3 | L12: 3.6 | M12: 0.003 | N12: -3.3 V | O12: -3.6 | P12: -3.3 | Q12: -3.2 | R12: 4e-05 | S12: Vdd 3 mA max; Vss 40 uA max. Control current (400 uA max) not included.
A13: TTL-1SP8T-183 | B13: 1.125 | C13: 0 | D13: 0 | E13: =IF(A13="","",IF(COUNT(B13:D13)<3,"Pending",B13+C13*D13)) | F13: Nominal +/-5 V x 200/25 mA maximum currents. RF loss and isolated-port dissipation not included. | H13: TTL-1SP8T-183.pdf, p.3 | I13: +5 V | J13: 4.75 | K13: 5 | L13: 5.25 | M13: 0.2 | N13: -5 V | O13: -5.25 | P13: -5 | Q13: -4.75 | R13: 0.025 | S13: Control current (100 uA/bit) not included.
A14: ANNE-50+ | B14: 0 | C14: 1 | D14: 1 | E14: =IF(A14="","",IF(COUNT(B14:D14)<3,"Pending",B14+C14*D14)) | F14: Assumes 1 W RF fully absorbed; check temperature derating (0.35 W rating at 100 C). | H14: ANNE-50+.pdf, p.1 | I14: None (passive) | S14: No DC supply.
A15: ZUDC10-5R23-S+ | B15: 0 | C15: 1 | D15: 0.18716948 | E15: =IF(A15="","",IF(COUNT(B15:D15)<3,"Pending",B15+C15*D15)) | F15: 1 W RF example, 0.9 dB mainline loss. Upper estimate: coupled/reflected output is not internal heat. | H15: ZUDC10-5R23-S+.pdf, electrical specifications | I15: None (passive) | S15: No DC supply.
A16: ZVDC-20-0123+ | B16: 0 | C16: 1 | D16: 0.20567177 | E16: =IF(A16="","",IF(COUNT(B16:D16)<3,"Pending",B16+C16*D16)) | F16: 1 W RF example, 1.0 dB mainline loss. Upper estimate: coupled/reflected output is not internal heat. | H16: ZVDC-20-0123+.pdf, electrical specifications | I16: None (passive) | S16: No DC supply.
A17: ZFDC-20-5+ | B17: 0 | C17: 1 | D17: 0.27556404 | E17: =IF(A17="","",IF(COUNT(B17:D17)<3,"Pending",B17+C17*D17)) | F17: 1 W RF example, mid-band 1.4 dB maximum mainline loss. Check actual band / input power limit. Coupled power included in bound. | H17: ZFDC-20-5+.pdf, electrical specifications | I17: None (passive) | S17: No DC supply.
A18: CS18SR5 | B18: 0 | C18: 1 | D18: 0.55225577 | E18: =IF(A18="","",IF(COUNT(B18:D18)<3,"Pending",B18+C18*D18)) | F18: 1 W RF example; both matched outputs; 6.5 dB loss to EACH output. Reflected input included in conservative bound. | H18: CS18SR5.pdf, p.1 | I18: None (passive) | S18: No DC supply.
A19: CS0520S | B19: 0 | C19: 1 | D19: 0.10874906 | E19: =IF(A19="","",IF(COUNT(B19:D19)<3,"Pending",B19+C19*D19)) | F19: 1 W RF example; 0.5 dB interpreted as excess loss over ideal split. Confirm manufacturer definition. Matched outputs. | H19: CS0520S.pdf, p.1 | I19: None (passive) | S19: No DC supply.
A20: SB-SF50-27+ | B20: 0 | C20: 1 | D20: 0.047203836 | E20: =IF(A20="","",IF(COUNT(B20:D20)<3,"Pending",B20+C20*D20)) | F20: 1 W RF example; 0.21 dB maximum at 18-27 GHz. Reflected input included in conservative bound. | H20: No SB-SF50-27+ datasheet in the Component Datasheets folder; values unverified. | I20: None (passive) | S20: No DC supply.
A21: PD-0500-2S (1-250 MHz) | B21: 0 | C21: 8 | D21: 0.087989161 | E21: =IF(A21="","",IF(COUNT(B21:D21)<3,"Pending",B21+C21*D21)) | F21: 8 W rated input, matched loads; 0.4 dB treated as excess loss. | H21: PD-0500-2S.pdf, p.1 | I21: None (passive) | S21: No DC supply.
A22: PD-0500-2S (250-500 MHz) | B22: 0 | C22: 8 | D22: 0.20567177 | E22: =IF(A22="","",IF(COUNT(B22:D22)<3,"Pending",B22+C22*D22)) | F22: 8 W rated input, matched loads; 1.0 dB treated as excess loss. | H22: PD-0500-2S.pdf, p.1 | I22: None (passive) | S22: No DC supply.
A23: PD-E000-2S | B23: 0 | C23: 10 | D23: 0.087989161 | E23: =IF(A23="","",IF(COUNT(B23:D23)<3,"Pending",B23+C23*D23)) | F23: 10 W input example at rated power; matched-load estimate using 0.4 dB excess loss. | H23: PD-E000-2S.pdf, p.1 | I23: None (passive) | S23: No DC supply.
A24: PD-F000-2S | B24: 0 | C24: 10 | D24: 0.12903641 | E24: =IF(A24="","",IF(COUNT(B24:D24)<3,"Pending",B24+C24*D24)) | F24: 10 W input example at rated power; matched-load estimate using 0.6 dB excess loss. | H24: PD-F000-2S.pdf, p.1 | I24: None (passive) | S24: No DC supply.
A25: PD-S000-2S | B25: 0 | C25: 10 | D25: 0.25868976 | E25: =IF(A25="","",IF(COUNT(B25:D25)<3,"Pending",B25+C25*D25)) | F25: 10 W input example at rated power; matched-load estimate using 1.3 dB excess loss. | H25: PD-S000-2S.pdf, p.1 | I25: None (passive) | S25: No DC supply.
... A28: ZX10R-2-183-S+ | B28: 0 | C28: 0.6 | D28: 0.64434412 | E28: =IF(A28="","",IF(COUNT(B28:D28)<3,"Pending",B28+C28*D28)) | F28: 0.6 W rated splitter input; 4.5 dB max insertion loss above 3 dB (7.5 dB to each output). Within 0.6 W internal dissipation rating. | H28: ZX10R-2-183-S+.pdf, p.2 | I28: None (passive) | S28: No DC supply.
A29: 50P-2101 | B29: 0.01 | C29: 0.25118864 | D29: 1 | E29: =IF(A29="","",IF(COUNT(B29:D29)<3,"Pending",B29+C29*D29)) | F29: +5 V x 2 mA nominal DC; assumes all +24 dBm rated operating RF input absorbed at high attenuation (same basis as ZX76-31A-PNS+). | H29: 50P-2101.pdf, p.1 | I29: +5 V | K29: 5 | M29: 0.002 | S29: +5 Vdc at 2 mA nominal; datasheet gives no voltage tolerance or maximum current.
A30: BW-S0.5W2+ | B30: 0 | C30: 2 | D30: 0.16824 | E30: =IF(A30="","",IF(COUNT(B30:D30)<3,"Pending",B30+C30*D30)) | F30: 2 W rated input; 0.8 dB maximum attenuation dissipated. | H30: BW-S0.5W2+.pdf, p.2 | I30: None (passive) | S30: No DC supply.
A31: RFLT8WDC40G | B31: 0 | C31: 1 | D31: 0.95991 | E31: =IF(A31="","",IF(COUNT(B31:D31)<3,"Pending",B31+C31*D31)) | F31: 1 W rated forward power, matched loads; 23 dB max insertion loss to each of 8 outputs. | H31: RFLT8WDC40G.pdf, p.1 | I31: None (passive) | S31: No DC supply.
A32: ZX76-24G-30-S+ | B32: 0.001482 | C32: 0.15848932 | D32: 1 | E32: =IF(A32="","",IF(COUNT(B32:D32)<3,"Pending",B32+C32*D32)) | F32: Max supply V x max current; assumes +22 dBm (P1dB min) RF input fully absorbed at high attenuation. | H32: ZX76-24G-30-S+_dashboard.pdf, pp.1-2 | I32: +3.3 V | J32: 2.33 | K32: 3.3 | L32: 5.4 | M32: 0.00025 | N32: -3 V | O32: -3.3 | P32: -3 | Q32: -2.7 | R32: 4e-05 | S32: Vdd min is 3.1 V when Vss is supplied externally. Grounding Vss uses the internal negative generator (rail 2 then not needed).
A33: ZN2PD-02183-S+ | B33: 0 | C33: 10 | D33: 0.20567177 | E33: =IF(A33="","",IF(COUNT(B33:D33)<3,"Pending",B33+C33*D33)) | F33: 10 W rated splitter input, matched loads; 1.0 dB max excess loss over 3 dB split. | H33: ZN2PD-02183-S+.pdf, p.2 | I33: None (passive) | S33: No DC supply.
A34: ZN2PD-9G-S+ (1.7-6.8 GHz) | B34: 0 | C34: 30 | D34: 0.24142242 | E34: =IF(A34="","",IF(COUNT(B34:D34)<3,"Pending",B34+C34*D34)) | F34: 30 W rated splitter input, matched loads; 1.2 dB max excess loss. Datasheet requires heat sinking (60 C base plate) at this power. | H34: ZN2PD-9G-S+.pdf, p.2 | I34: None (passive) | S34: No DC supply.
A35: ZN2PD-9G-S+ (6.8-9 GHz) | B35: 0 | C35: 20 | D35: 0.27556404 | E35: =IF(A35="","",IF(COUNT(B35:D35)<3,"Pending",B35+C35*D35)) | F35: 20 W rated splitter input, matched loads; 1.4 dB max excess loss. | H35: ZN2PD-9G-S+.pdf, p.2 | I35: None (passive) | S35: No DC supply.
A36: PA-124-D (all cells energized) | B36: 12.096 | C36: 2 | D36: 1 | E36: =IF(A36="","",IF(COUNT(B36:D36)<3,"Pending",B36+C36*D36)) | F36: Worst case: all 4 failsafe 28 V coils energized (28 V x 108 mA x 4). Assumes 2 W rated RF fully absorbed at 15 dB. Coil heat depends on attenuation state. | H36: PA-124-D.pdf, p.1 | I36: +28 V | K36: 28 | M36: 0.432 | S36: 108 mA nominal per cell x 4 cells; datasheet gives no voltage tolerance or maximum current.
A37: ADP-SMAF-SMAF-F-G | B37: 0 | C37: 0 | D37: 0 | E37: =IF(A37="","",IF(COUNT(B37:D37)<3,"Pending",B37+C37*D37)) | F37: Passive SMA female-female flange-mount adapter; heat negligible. | H37: ADP-SMAF-SMAF-F-G.pdf, pp.1-2 | I37: None (passive) | S37: No DC supply.
A38: OD3010-05HB fan | B38: 1.4 | C38: 0 | D38: 0 | E38: =IF(A38="","",IF(COUNT(B38:D38)<3,"Pending",B38+C38*D38)) | F38: Rated input power (5 V x 0.28 A). Counts as enclosure heat only if the fan is inside the enclosure. | H38: Fan OD3010.pdf, p.1 (tach/alarm/PWM variants identical) | I38: +5 V | J38: 4.5 | K38: 5 | L38: 5.5 | M38: 0.28 | S38: Rated current (no separate maximum or start-up current given).
A39: OD3010-05MB fan | B39: 1.1 | C39: 0 | D39: 0 | E39: =IF(A39="","",IF(COUNT(B39:D39)<3,"Pending",B39+C39*D39)) | F39: Rated input power (5 V x 0.21 A). Counts as enclosure heat only if the fan is inside the enclosure. | H39: Fan OD3010.pdf, p.1 (tach/alarm/PWM variants identical) | I39: +5 V | J39: 4.5 | K39: 5 | L39: 5.5 | M39: 0.21 | S39: Rated current (no separate maximum or start-up current given).
A40: OD3010-05LB fan | B40: 0.9 | C40: 0 | D40: 0 | E40: =IF(A40="","",IF(COUNT(B40:D40)<3,"Pending",B40+C40*D40)) | F40: Rated input power (5 V x 0.18 A). Counts as enclosure heat only if the fan is inside the enclosure. | H40: Fan OD3010.pdf, p.1 (tach/alarm/PWM variants identical) | I40: +5 V | J40: 4.5 | K40: 5 | L40: 5.5 | M40: 0.18 | S40: Rated current (no separate maximum or start-up current given).
A41: OD3010-12HB fan | B41: 1.8 | C41: 0 | D41: 0 | E41: =IF(A41="","",IF(COUNT(B41:D41)<3,"Pending",B41+C41*D41)) | F41: Rated input power (12 V x 0.15 A). Counts as enclosure heat only if the fan is inside the enclosure. | H41: Fan OD3010.pdf, p.1 (tach/alarm/PWM variants identical) | I41: +12 V | J41: 11 | K41: 12 | L41: 13.8 | M41: 0.15 | S41: Rated current (no separate maximum or start-up current given).
A42: OD3010-12MB fan | B42: 1.5 | C42: 0 | D42: 0 | E42: =IF(A42="","",IF(COUNT(B42:D42)<3,"Pending",B42+C42*D42)) | F42: Rated input power (12 V x 0.12 A). Counts as enclosure heat only if the fan is inside the enclosure. | H42: Fan OD3010.pdf, p.1 (tach/alarm/PWM variants identical) | I42: +12 V | J42: 11 | K42: 12 | L42: 13.8 | M42: 0.12 | S42: Rated current (no separate maximum or start-up current given).
A43: OD3010-12LB fan | B43: 1.2 | C43: 0 | D43: 0 | E43: =IF(A43="","",IF(COUNT(B43:D43)<3,"Pending",B43+C43*D43)) | F43: Rated input power (12 V x 0.10 A). Counts as enclosure heat only if the fan is inside the enclosure. | H43: Fan OD3010.pdf, p.1 (tach/alarm/PWM variants identical) | I43: +12 V | J43: 11 | K43: 12 | L43: 13.8 | M43: 0.1 | S43: Rated current (no separate maximum or start-up current given).
E44: =IF(A44="","",IF(COUNT(B44:D44)<3,"Pending",B44+C44*D44))
...
